I was unable to work with dataset 1 from pypi and the error message is shown in the screenshot.